2025-03-30 11:12:47.102802: E external/local_xla/xla/stream_executor/cuda/cuda_fft.cc:477] Unable to register cuFFT factory: Attempting to register factory for plugin cuFFT when one has already been registered
WARNING: All log messages before absl::InitializeLog() is called are written to STDERR
E0000 00:00:1743333167.157574   76203 cuda_dnn.cc:8310] Unable to register cuDNN factory: Attempting to register factory for plugin cuDNN when one has already been registered
E0000 00:00:1743333167.171842   76203 cuda_blas.cc:1418] Unable to register cuBLAS factory: Attempting to register factory for plugin cuBLAS when one has already been registered
2025-03-30 11:12:47.217054: I tensorflow/core/platform/cpu_feature_guard.cc:210] This TensorFlow binary is optimized to use available CPU instructions in performance-critical operations.
To enable the following instructions: AVX2 FMA, in other operations, rebuild TensorFlow with the appropriate compiler flags.
test_dropout_variability (test_attention.TestMultiHeadFAVORAttention.test_dropout_variability) ... 2025-03-30 11:12:52.964547: E external/local_xla/xla/stream_executor/cuda/cuda_driver.cc:152] failed call to cuInit: INTERNAL: CUDA error: Failed call to cuInit: UNKNOWN ERROR (303)
WARNING: All log messages before absl::InitializeLog() is called are written to STDERR
I0000 00:00:1743333173.370020   76203 service.cc:148] XLA service 0x9b69fc0 initialized for platform Host (this does not guarantee that XLA will be used). Devices:
I0000 00:00:1743333173.370130   76203 service.cc:156]   StreamExecutor device (0): Host, Default Version
I0000 00:00:1743333173.387143   76203 device_compiler.h:188] Compiled cluster using XLA!  This line is logged at most once for the lifetime of the process.
2025-03-30 11:12:53.950502: I tensorflow/core/framework/local_rendezvous.cc:405] Local rendezvous is aborting with status: INVALID_ARGUMENT: Matrix size-incompatible: In[0]: [80,8], In[1]: [4,8]
ERROR
test_inference_determinism (test_attention.TestMultiHeadFAVORAttention.test_inference_determinism) ... WARNING:tensorflow:5 out of the last 5 calls to <function conv.<locals>._conv_xla at 0x7ea8101b1a80> triggered tf.function retracing. Tracing is expensive and the excessive number of tracings could be due to (1) creating @tf.function repeatedly in a loop, (2) passing tensors with different shapes, (3) passing Python objects instead of tensors. For (1), please define your @tf.function outside of the loop. For (2), @tf.function has reduce_retracing=True option that can avoid unnecessary retracing. For (3), please refer to https://www.tensorflow.org/guide/function#controlling_retracing and https://www.tensorflow.org/api_docs/python/tf/function for  more details.
WARNING:tensorflow:6 out of the last 6 calls to <function conv.<locals>._conv_xla at 0x7ea8101b3920> triggered tf.function retracing. Tracing is expensive and the excessive number of tracings could be due to (1) creating @tf.function repeatedly in a loop, (2) passing tensors with different shapes, (3) passing Python objects instead of tensors. For (1), please define your @tf.function outside of the loop. For (2), @tf.function has reduce_retracing=True option that can avoid unnecessary retracing. For (3), please refer to https://www.tensorflow.org/guide/function#controlling_retracing and https://www.tensorflow.org/api_docs/python/tf/function for  more details.
2025-03-30 11:12:54.548224: I tensorflow/core/framework/local_rendezvous.cc:405] Local rendezvous is aborting with status: INVALID_ARGUMENT: Matrix size-incompatible: In[0]: [80,8], In[1]: [4,8]
ERROR
test_no_nan_values (test_attention.TestMultiHeadFAVORAttention.test_no_nan_values) ... ERROR
test_output_shape (test_attention.TestMultiHeadFAVORAttention.test_output_shape) ... 2025-03-30 11:12:55.691900: I tensorflow/core/framework/local_rendezvous.cc:405] Local rendezvous is aborting with status: INVALID_ARGUMENT: Matrix size-incompatible: In[0]: [80,8], In[1]: [4,8]
ERROR
test_dropout_inference (test_conv.TestGroupedPointwiseConv1D.test_dropout_inference) ... ok
test_dropout_training_variability (test_conv.TestGroupedPointwiseConv1D.test_dropout_training_variability) ... ok
test_invalid_group_channels (test_conv.TestGroupedPointwiseConv1D.test_invalid_group_channels) ... ok
test_output_shape (test_conv.TestGroupedPointwiseConv1D.test_output_shape) ... ok
test_empty_token_sequence (test_edge_cases.TestEdgeCases.test_empty_token_sequence) ... ok
test_invalid_group_configuration (test_edge_cases.TestEdgeCases.test_invalid_group_configuration) ... ok
test_inference_determinism (test_embeddings.TestTokenRepresentation.test_inference_determinism) ... ok
test_output_shape (test_embeddings.TestTokenRepresentation.test_output_shape) ... ok
test_call_output_shape (test_favor.TestFAVORProjection.test_call_output_shape) ... ok
test_call_output_values (test_favor.TestFAVORProjection.test_call_output_values) ... ok
test_weight_shapes (test_favor.TestFAVORProjection.test_weight_shapes) ... ok
test_forward_pass (test_integration.TestIntegration.test_forward_pass) ... ERROR
test_inference_determinism (test_lm.TestPaimcsLM.test_inference_determinism) ... ERROR
test_output_shape (test_lm.TestPaimcsLM.test_output_shape) ... ERROR
test_training_dropout_variability (test_lm.TestPaimcsLM.test_training_dropout_variability) ... ERROR
test_deterministic_inference (test_multiscale.TestMultiScaleKernelFeatures.test_deterministic_inference) ... 2025-03-30 11:13:02.155551: I tensorflow/core/framework/local_rendezvous.cc:405] Local rendezvous is aborting with status: INVALID_ARGUMENT: Incompatible shapes: [4,8] vs. [16]
ERROR
test_dropout_training_variability (test_multiscale.TestMultiScaleKernelFeatures.test_dropout_training_variability) ... ERROR
test_output_shape (test_multiscale.TestMultiScaleKernelFeatures.test_output_shape) ... ERROR
test_build_and_call (test_norms.TestRMSNorm.test_build_and_call) ... ERROR
test_invalid_input_shape (test_norms.TestRMSNorm.test_invalid_input_shape) ... ok
test_call_output_shape (test_nystrom.TestNystromFeatures.test_call_output_shape) ... ok
test_landmarks_shape (test_nystrom.TestNystromFeatures.test_landmarks_shape) ... ok
test_output_value_range (test_nystrom.TestNystromFeatures.test_output_value_range) ... ok
test_dropout_behavior (test_orthogonal.TestOrthogonalRandomFeaturesTF.test_dropout_behavior) ... ERROR
test_output_shape (test_orthogonal.TestOrthogonalRandomFeaturesTF.test_output_shape) ... ERROR
test_output_value_range (test_orthogonal.TestOrthogonalRandomFeaturesTF.test_output_value_range) ... ERROR
test_weight_and_bias_shapes (test_orthogonal.TestOrthogonalRandomFeaturesTF.test_weight_and_bias_shapes) ... ERROR
test_forward_pass_time (test_performance.TestPerformance.test_forward_pass_time) ... ERROR
test_dropout_variability (test_performer.TestKernelLMBlock.test_dropout_variability) ... 2025-03-30 11:13:04.815331: I tensorflow/core/framework/local_rendezvous.cc:405] Local rendezvous is aborting with status: INVALID_ARGUMENT: Matrix size-incompatible: In[0]: [80,8], In[1]: [4,8]
ERROR
test_inference_determinism (test_performer.TestKernelLMBlock.test_inference_determinism) ... ERROR
test_output_shape (test_performer.TestKernelLMBlock.test_output_shape) ... ERROR
test_call_output_shape (test_pos_encode.TestPositionalEncoding.test_call_output_shape) ... ok
test_call_output_values (test_pos_encode.TestPositionalEncoding.test_call_output_values) ... ok
test_pos_encoding_shape_and_dtype (test_pos_encode.TestPositionalEncoding.test_pos_encoding_shape_and_dtype) ... ok
test_dropout_effect_in_training (test_projection.TestProjectionWithKernel.test_dropout_effect_in_training) ... ok
test_inference_determinism (test_projection.TestProjectionWithKernel.test_inference_determinism) ... ok
test_output_shape (test_projection.TestProjectionWithKernel.test_output_shape) ... ok
test_reproducible_output (test_reproducibility.TestReproducibility.test_reproducible_output) ... ERROR
test_identity_when_sin_zero_and_cos_one (test_rope.TestApplyRotaryPosEmb.test_identity_when_sin_zero_and_cos_one) ... ok
test_output_shape (test_rope.TestApplyRotaryPosEmb.test_output_shape) ... ok
test_rotary_embedding_invalid_head_dim (test_rope.TestRotaryEmbedding.test_rotary_embedding_invalid_head_dim) ... ok
test_rotary_embedding_shapes (test_rope.TestRotaryEmbedding.test_rotary_embedding_shapes) ... ok

======================================================================
ERROR: test_dropout_variability (test_attention.TestMultiHeadFAVORAttention.test_dropout_variability)
----------------------------------------------------------------------
Traceback (most recent call last):
  File "/content/PAIMCS_model/test_paimcs/test_attention.py", line 67, in test_dropout_variability
    output_train1 = layer_dropout(self.input_tensor, training=True)
                    ^^^^^^^^^^^^^^^^^^^^^^^^^^^^^^^^^^^^^^^^^^^^^^^
  File "/usr/local/lib/python3.11/dist-packages/keras/src/utils/traceback_utils.py", line 122, in error_handler
    raise e.with_traceback(filtered_tb) from None
  File "/content/PAIMCS_model/paimcs/attention.py", line 63, in call
    k_prime = self.favor_proj(k) # (batch, num_heads, seq_len, num_random_features)
              ^^^^^^^^^^^^^^^^^^
  File "/content/PAIMCS_model/paimcs/favor.py", line 35, in call
    x_proj = tensordot(x, self.W, axes=1) + self.bias
             ^^^^^^^^^^^^^^^^^^^^^^^^^^^^
tensorflow.python.framework.errors_impl.InvalidArgumentError: Exception encountered when calling FAVORProjection.call().

[1m{{function_node __wrapped__MatMul_device_/job:localhost/replica:0/task:0/device:CPU:0}} Matrix size-incompatible: In[0]: [80,8], In[1]: [4,8] [Op:MatMul] name: [0m

Arguments received by FAVORProjection.call():
  â€¢ x=tf.Tensor(shape=(2, 4, 10, 8), dtype=float16)

======================================================================
ERROR: test_inference_determinism (test_attention.TestMultiHeadFAVORAttention.test_inference_determinism)
----------------------------------------------------------------------
Traceback (most recent call last):
  File "/content/PAIMCS_model/test_paimcs/test_attention.py", line 46, in test_inference_determinism
    output1 = self.layer(self.input_tensor, training=False)
              ^^^^^^^^^^^^^^^^^^^^^^^^^^^^^^^^^^^^^^^^^^^^^
  File "/usr/local/lib/python3.11/dist-packages/keras/src/utils/traceback_utils.py", line 122, in error_handler
    raise e.with_traceback(filtered_tb) from None
  File "/content/PAIMCS_model/paimcs/attention.py", line 63, in call
    k_prime = self.favor_proj(k) # (batch, num_heads, seq_len, num_random_features)
              ^^^^^^^^^^^^^^^^^^
  File "/content/PAIMCS_model/paimcs/favor.py", line 35, in call
    x_proj = tensordot(x, self.W, axes=1) + self.bias
             ^^^^^^^^^^^^^^^^^^^^^^^^^^^^
tensorflow.python.framework.errors_impl.InvalidArgumentError: Exception encountered when calling FAVORProjection.call().

[1m{{function_node __wrapped__MatMul_device_/job:localhost/replica:0/task:0/device:CPU:0}} Matrix size-incompatible: In[0]: [80,8], In[1]: [4,8] [Op:MatMul] name: [0m

Arguments received by FAVORProjection.call():
  â€¢ x=tf.Tensor(shape=(2, 4, 10, 8), dtype=float16)

======================================================================
ERROR: test_no_nan_values (test_attention.TestMultiHeadFAVORAttention.test_no_nan_values)
----------------------------------------------------------------------
Traceback (most recent call last):
  File "/content/PAIMCS_model/test_paimcs/test_attention.py", line 51, in test_no_nan_values
    output = self.layer(self.input_tensor, training=False)
             ^^^^^^^^^^^^^^^^^^^^^^^^^^^^^^^^^^^^^^^^^^^^^
  File "/usr/local/lib/python3.11/dist-packages/keras/src/utils/traceback_utils.py", line 122, in error_handler
    raise e.with_traceback(filtered_tb) from None
  File "/content/PAIMCS_model/paimcs/attention.py", line 63, in call
    k_prime = self.favor_proj(k) # (batch, num_heads, seq_len, num_random_features)
              ^^^^^^^^^^^^^^^^^^
  File "/content/PAIMCS_model/paimcs/favor.py", line 35, in call
    x_proj = tensordot(x, self.W, axes=1) + self.bias
             ^^^^^^^^^^^^^^^^^^^^^^^^^^^^
tensorflow.python.framework.errors_impl.InvalidArgumentError: Exception encountered when calling FAVORProjection.call().

[1m{{function_node __wrapped__MatMul_device_/job:localhost/replica:0/task:0/device:CPU:0}} Matrix size-incompatible: In[0]: [80,8], In[1]: [4,8] [Op:MatMul] name: [0m

Arguments received by FAVORProjection.call():
  â€¢ x=tf.Tensor(shape=(2, 4, 10, 8), dtype=float16)

======================================================================
ERROR: test_output_shape (test_attention.TestMultiHeadFAVORAttention.test_output_shape)
----------------------------------------------------------------------
Traceback (most recent call last):
  File "/content/PAIMCS_model/test_paimcs/test_attention.py", line 40, in test_output_shape
    output = self.layer(self.input_tensor, training=False)
             ^^^^^^^^^^^^^^^^^^^^^^^^^^^^^^^^^^^^^^^^^^^^^
  File "/usr/local/lib/python3.11/dist-packages/keras/src/utils/traceback_utils.py", line 122, in error_handler
    raise e.with_traceback(filtered_tb) from None
  File "/content/PAIMCS_model/paimcs/attention.py", line 63, in call
    k_prime = self.favor_proj(k) # (batch, num_heads, seq_len, num_random_features)
              ^^^^^^^^^^^^^^^^^^
  File "/content/PAIMCS_model/paimcs/favor.py", line 35, in call
    x_proj = tensordot(x, self.W, axes=1) + self.bias
             ^^^^^^^^^^^^^^^^^^^^^^^^^^^^
tensorflow.python.framework.errors_impl.InvalidArgumentError: Exception encountered when calling FAVORProjection.call().

[1m{{function_node __wrapped__MatMul_device_/job:localhost/replica:0/task:0/device:CPU:0}} Matrix size-incompatible: In[0]: [80,8], In[1]: [4,8] [Op:MatMul] name: [0m

Arguments received by FAVORProjection.call():
  â€¢ x=tf.Tensor(shape=(2, 4, 10, 8), dtype=float16)

======================================================================
ERROR: test_forward_pass (test_integration.TestIntegration.test_forward_pass)
----------------------------------------------------------------------
Traceback (most recent call last):
  File "/content/PAIMCS_model/test_paimcs/test_integration.py", line 46, in test_forward_pass
    logits = self.model(self.token_seq, training=False)
             ^^^^^^^^^^^^^^^^^^^^^^^^^^^^^^^^^^^^^^^^^^
  File "/usr/local/lib/python3.11/dist-packages/keras/src/utils/traceback_utils.py", line 122, in error_handler
    raise e.with_traceback(filtered_tb) from None
  File "/content/PAIMCS_model/paimcs/lm.py", line 48, in call
    x = block(x, training=training)
        ^^^^^^^^^^^^^^^^^^^^^^^^^^^
  File "/content/PAIMCS_model/paimcs/performer.py", line 28, in call
    attn_out = self.attn(x, training=training)
               ^^^^^^^^^^^^^^^^^^^^^^^^^^^^^^^
  File "/content/PAIMCS_model/paimcs/attention.py", line 69, in call
    kv = einsum('bhse,bhsd->bhed', k_prime, v)
         ^^^^^^^^^^^^^^^^^^^^^^^^^^^^^^^^^^^^^
tensorflow.python.framework.errors_impl.InvalidArgumentError: Exception encountered when calling MultiHeadFAVORAttention.call().

[1mcannot compute Einsum as input #1(zero-based) was expected to be a half tensor but is a float tensor [Op:Einsum] name: [0m

Arguments received by MultiHeadFAVORAttention.call():
  â€¢ x=tf.Tensor(shape=(2, 15, 16), dtype=float16)
  â€¢ training=False

======================================================================
ERROR: test_inference_determinism (test_lm.TestPaimcsLM.test_inference_determinism)
----------------------------------------------------------------------
Traceback (most recent call last):
  File "/content/PAIMCS_model/test_paimcs/test_lm.py", line 54, in test_inference_determinism
    output1 = self.model(self.token_seq, training=False)
              ^^^^^^^^^^^^^^^^^^^^^^^^^^^^^^^^^^^^^^^^^^
  File "/usr/local/lib/python3.11/dist-packages/keras/src/utils/traceback_utils.py", line 122, in error_handler
    raise e.with_traceback(filtered_tb) from None
  File "/content/PAIMCS_model/paimcs/lm.py", line 48, in call
    x = block(x, training=training)
        ^^^^^^^^^^^^^^^^^^^^^^^^^^^
  File "/content/PAIMCS_model/paimcs/performer.py", line 28, in call
    attn_out = self.attn(x, training=training)
               ^^^^^^^^^^^^^^^^^^^^^^^^^^^^^^^
  File "/content/PAIMCS_model/paimcs/attention.py", line 63, in call
    k_prime = self.favor_proj(k) # (batch, num_heads, seq_len, num_random_features)
              ^^^^^^^^^^^^^^^^^^
  File "/content/PAIMCS_model/paimcs/favor.py", line 35, in call
    x_proj = tensordot(x, self.W, axes=1) + self.bias
             ^^^^^^^^^^^^^^^^^^^^^^^^^^^^
tensorflow.python.framework.errors_impl.InvalidArgumentError: Exception encountered when calling FAVORProjection.call().

[1m{{function_node __wrapped__MatMul_device_/job:localhost/replica:0/task:0/device:CPU:0}} Matrix size-incompatible: In[0]: [320,8], In[1]: [4,8] [Op:MatMul] name: [0m

Arguments received by FAVORProjection.call():
  â€¢ x=tf.Tensor(shape=(4, 4, 20, 8), dtype=float16)

======================================================================
ERROR: test_output_shape (test_lm.TestPaimcsLM.test_output_shape)
----------------------------------------------------------------------
Traceback (most recent call last):
  File "/content/PAIMCS_model/test_paimcs/test_lm.py", line 49, in test_output_shape
    logits = self.model(self.token_seq, training=False)
             ^^^^^^^^^^^^^^^^^^^^^^^^^^^^^^^^^^^^^^^^^^
  File "/usr/local/lib/python3.11/dist-packages/keras/src/utils/traceback_utils.py", line 122, in error_handler
    raise e.with_traceback(filtered_tb) from None
  File "/content/PAIMCS_model/paimcs/lm.py", line 48, in call
    x = block(x, training=training)
        ^^^^^^^^^^^^^^^^^^^^^^^^^^^
  File "/content/PAIMCS_model/paimcs/performer.py", line 28, in call
    attn_out = self.attn(x, training=training)
               ^^^^^^^^^^^^^^^^^^^^^^^^^^^^^^^
  File "/content/PAIMCS_model/paimcs/attention.py", line 63, in call
    k_prime = self.favor_proj(k) # (batch, num_heads, seq_len, num_random_features)
              ^^^^^^^^^^^^^^^^^^
  File "/content/PAIMCS_model/paimcs/favor.py", line 35, in call
    x_proj = tensordot(x, self.W, axes=1) + self.bias
             ^^^^^^^^^^^^^^^^^^^^^^^^^^^^
tensorflow.python.framework.errors_impl.InvalidArgumentError: Exception encountered when calling FAVORProjection.call().

[1m{{function_node __wrapped__MatMul_device_/job:localhost/replica:0/task:0/device:CPU:0}} Matrix size-incompatible: In[0]: [320,8], In[1]: [4,8] [Op:MatMul] name: [0m

Arguments received by FAVORProjection.call():
  â€¢ x=tf.Tensor(shape=(4, 4, 20, 8), dtype=float16)

======================================================================
ERROR: test_training_dropout_variability (test_lm.TestPaimcsLM.test_training_dropout_variability)
----------------------------------------------------------------------
Traceback (most recent call last):
  File "/content/PAIMCS_model/test_paimcs/test_lm.py", line 75, in test_training_dropout_variability
    out_train1 = model_dropout(self.token_seq, training=True)
                 ^^^^^^^^^^^^^^^^^^^^^^^^^^^^^^^^^^^^^^^^^^^^
  File "/usr/local/lib/python3.11/dist-packages/keras/src/utils/traceback_utils.py", line 122, in error_handler
    raise e.with_traceback(filtered_tb) from None
  File "/content/PAIMCS_model/paimcs/lm.py", line 48, in call
    x = block(x, training=training)
        ^^^^^^^^^^^^^^^^^^^^^^^^^^^
  File "/content/PAIMCS_model/paimcs/performer.py", line 28, in call
    attn_out = self.attn(x, training=training)
               ^^^^^^^^^^^^^^^^^^^^^^^^^^^^^^^
  File "/content/PAIMCS_model/paimcs/attention.py", line 63, in call
    k_prime = self.favor_proj(k) # (batch, num_heads, seq_len, num_random_features)
              ^^^^^^^^^^^^^^^^^^
  File "/content/PAIMCS_model/paimcs/favor.py", line 35, in call
    x_proj = tensordot(x, self.W, axes=1) + self.bias
             ^^^^^^^^^^^^^^^^^^^^^^^^^^^^
tensorflow.python.framework.errors_impl.InvalidArgumentError: Exception encountered when calling FAVORProjection.call().

[1m{{function_node __wrapped__MatMul_device_/job:localhost/replica:0/task:0/device:CPU:0}} Matrix size-incompatible: In[0]: [320,8], In[1]: [4,8] [Op:MatMul] name: [0m

Arguments received by FAVORProjection.call():
  â€¢ x=tf.Tensor(shape=(4, 4, 20, 8), dtype=float16)

======================================================================
ERROR: test_deterministic_inference (test_multiscale.TestMultiScaleKernelFeatures.test_deterministic_inference)
----------------------------------------------------------------------
Traceback (most recent call last):
  File "/content/PAIMCS_model/test_paimcs/test_multiscale.py", line 34, in test_deterministic_inference
    output1 = self.layer(self.input_tensor, training=False)
              ^^^^^^^^^^^^^^^^^^^^^^^^^^^^^^^^^^^^^^^^^^^^^
  File "/usr/local/lib/python3.11/dist-packages/keras/src/utils/traceback_utils.py", line 122, in error_handler
    raise e.with_traceback(filtered_tb) from None
  File "/content/PAIMCS_model/paimcs/multiscale.py", line 21, in call
    features = [scale(x, training=training) for scale in self.scales]
               ^^^^^^^^^^^^^^^^^^^^^^^^^^^^^^^^^^^^^^^^^^^^^^^^^^^^^^
  File "/content/PAIMCS_model/paimcs/multiscale.py", line 21, in <listcomp>
    features = [scale(x, training=training) for scale in self.scales]
                ^^^^^^^^^^^^^^^^^^^^^^^^^^^
  File "/content/PAIMCS_model/paimcs/orthogonal.py", line 44, in call
    projection = tf.tensordot(x, self.W, axes=1) + self.b
                 ~~~~~~~~~~~~~~~~~~~~~~~~~~~~~~~~^~~~~~~~
tensorflow.python.framework.errors_impl.InvalidArgumentError: Exception encountered when calling OrthogonalRandomFeaturesTF.call().

[1m{{function_node __wrapped__AddV2_device_/job:localhost/replica:0/task:0/device:CPU:0}} Incompatible shapes: [4,8] vs. [16] [Op:AddV2] name: [0m

Arguments received by OrthogonalRandomFeaturesTF.call():
  â€¢ x=tf.Tensor(shape=(4, 8), dtype=float16)
  â€¢ training=False

======================================================================
ERROR: test_dropout_training_variability (test_multiscale.TestMultiScaleKernelFeatures.test_dropout_training_variability)
----------------------------------------------------------------------
Traceback (most recent call last):
  File "/content/PAIMCS_model/test_paimcs/test_multiscale.py", line 46, in test_dropout_training_variability
    output_train1 = dropout_layer(self.input_tensor, training=True)
                    ^^^^^^^^^^^^^^^^^^^^^^^^^^^^^^^^^^^^^^^^^^^^^^^
  File "/usr/local/lib/python3.11/dist-packages/keras/src/utils/traceback_utils.py", line 122, in error_handler
    raise e.with_traceback(filtered_tb) from None
  File "/content/PAIMCS_model/paimcs/multiscale.py", line 21, in call
    features = [scale(x, training=training) for scale in self.scales]
               ^^^^^^^^^^^^^^^^^^^^^^^^^^^^^^^^^^^^^^^^^^^^^^^^^^^^^^
  File "/content/PAIMCS_model/paimcs/multiscale.py", line 21, in <listcomp>
    features = [scale(x, training=training) for scale in self.scales]
                ^^^^^^^^^^^^^^^^^^^^^^^^^^^
  File "/content/PAIMCS_model/paimcs/orthogonal.py", line 44, in call
    projection = tf.tensordot(x, self.W, axes=1) + self.b
                 ~~~~~~~~~~~~~~~~~~~~~~~~~~~~~~~~^~~~~~~~
tensorflow.python.framework.errors_impl.InvalidArgumentError: Exception encountered when calling OrthogonalRandomFeaturesTF.call().

[1m{{function_node __wrapped__AddV2_device_/job:localhost/replica:0/task:0/device:CPU:0}} Incompatible shapes: [4,8] vs. [16] [Op:AddV2] name: [0m

Arguments received by OrthogonalRandomFeaturesTF.call():
  â€¢ x=tf.Tensor(shape=(4, 8), dtype=float16)
  â€¢ training=True

======================================================================
ERROR: test_output_shape (test_multiscale.TestMultiScaleKernelFeatures.test_output_shape)
----------------------------------------------------------------------
Traceback (most recent call last):
  File "/content/PAIMCS_model/test_paimcs/test_multiscale.py", line 28, in test_output_shape
    output = self.layer(self.input_tensor, training=False)
             ^^^^^^^^^^^^^^^^^^^^^^^^^^^^^^^^^^^^^^^^^^^^^
  File "/usr/local/lib/python3.11/dist-packages/keras/src/utils/traceback_utils.py", line 122, in error_handler
    raise e.with_traceback(filtered_tb) from None
  File "/content/PAIMCS_model/paimcs/multiscale.py", line 21, in call
    features = [scale(x, training=training) for scale in self.scales]
               ^^^^^^^^^^^^^^^^^^^^^^^^^^^^^^^^^^^^^^^^^^^^^^^^^^^^^^
  File "/content/PAIMCS_model/paimcs/multiscale.py", line 21, in <listcomp>
    features = [scale(x, training=training) for scale in self.scales]
                ^^^^^^^^^^^^^^^^^^^^^^^^^^^
  File "/content/PAIMCS_model/paimcs/orthogonal.py", line 44, in call
    projection = tf.tensordot(x, self.W, axes=1) + self.b
                 ~~~~~~~~~~~~~~~~~~~~~~~~~~~~~~~~^~~~~~~~
tensorflow.python.framework.errors_impl.InvalidArgumentError: Exception encountered when calling OrthogonalRandomFeaturesTF.call().

[1m{{function_node __wrapped__AddV2_device_/job:localhost/replica:0/task:0/device:CPU:0}} Incompatible shapes: [4,8] vs. [16] [Op:AddV2] name: [0m

Arguments received by OrthogonalRandomFeaturesTF.call():
  â€¢ x=tf.Tensor(shape=(4, 8), dtype=float16)
  â€¢ training=False

======================================================================
ERROR: test_build_and_call (test_norms.TestRMSNorm.test_build_and_call)
----------------------------------------------------------------------
Traceback (most recent call last):
  File "/content/PAIMCS_model/test_paimcs/test_norms.py", line 15, in test_build_and_call
    y = self.layer(x)
        ^^^^^^^^^^^^^
  File "/usr/local/lib/python3.11/dist-packages/keras/src/utils/traceback_utils.py", line 122, in error_handler
    raise e.with_traceback(filtered_tb) from None
  File "/content/PAIMCS_model/paimcs/norms.py", line 15, in build
    if input_shape.rank is None or input_shape[-1] is None:
       ^^^^^^^^^^^^^^^^
AttributeError: 'tuple' object has no attribute 'rank'

======================================================================
ERROR: test_dropout_behavior (test_orthogonal.TestOrthogonalRandomFeaturesTF.test_dropout_behavior)
----------------------------------------------------------------------
Traceback (most recent call last):
  File "/content/PAIMCS_model/test_paimcs/test_orthogonal.py", line 63, in test_dropout_behavior
    _ = layer_dropout(self.input_tensor, training=False)
        ^^^^^^^^^^^^^^^^^^^^^^^^^^^^^^^^^^^^^^^^^^^^^^^^
  File "/usr/local/lib/python3.11/dist-packages/keras/src/utils/traceback_utils.py", line 122, in error_handler
    raise e.with_traceback(filtered_tb) from None
  File "/content/PAIMCS_model/paimcs/orthogonal.py", line 44, in call
    projection = tf.tensordot(x, self.W, axes=1) + self.b
                 ~~~~~~~~~~~~~~~~~~~~~~~~~~~~~~~~^~~~~~~~
tensorflow.python.framework.errors_impl.InvalidArgumentError: Exception encountered when calling OrthogonalRandomFeaturesTF.call().

[1m{{function_node __wrapped__AddV2_device_/job:localhost/replica:0/task:0/device:CPU:0}} Incompatible shapes: [4,8] vs. [16] [Op:AddV2] name: [0m

Arguments received by OrthogonalRandomFeaturesTF.call():
  â€¢ x=tf.Tensor(shape=(4, 8), dtype=float16)
  â€¢ training=False

======================================================================
ERROR: test_output_shape (test_orthogonal.TestOrthogonalRandomFeaturesTF.test_output_shape)
----------------------------------------------------------------------
Traceback (most recent call last):
  File "/content/PAIMCS_model/test_paimcs/test_orthogonal.py", line 36, in test_output_shape
    output = self.layer(self.input_tensor, training=False)
             ^^^^^^^^^^^^^^^^^^^^^^^^^^^^^^^^^^^^^^^^^^^^^
  File "/usr/local/lib/python3.11/dist-packages/keras/src/utils/traceback_utils.py", line 122, in error_handler
    raise e.with_traceback(filtered_tb) from None
  File "/content/PAIMCS_model/paimcs/orthogonal.py", line 44, in call
    projection = tf.tensordot(x, self.W, axes=1) + self.b
                 ~~~~~~~~~~~~~~~~~~~~~~~~~~~~~~~~^~~~~~~~
tensorflow.python.framework.errors_impl.InvalidArgumentError: Exception encountered when calling OrthogonalRandomFeaturesTF.call().

[1m{{function_node __wrapped__AddV2_device_/job:localhost/replica:0/task:0/device:CPU:0}} Incompatible shapes: [4,8] vs. [16] [Op:AddV2] name: [0m

Arguments received by OrthogonalRandomFeaturesTF.call():
  â€¢ x=tf.Tensor(shape=(4, 8), dtype=float16)
  â€¢ training=False

======================================================================
ERROR: test_output_value_range (test_orthogonal.TestOrthogonalRandomFeaturesTF.test_output_value_range)
----------------------------------------------------------------------
Traceback (most recent call last):
  File "/content/PAIMCS_model/test_paimcs/test_orthogonal.py", line 45, in test_output_value_range
    output = self.layer(self.input_tensor, training=False)
             ^^^^^^^^^^^^^^^^^^^^^^^^^^^^^^^^^^^^^^^^^^^^^
  File "/usr/local/lib/python3.11/dist-packages/keras/src/utils/traceback_utils.py", line 122, in error_handler
    raise e.with_traceback(filtered_tb) from None
  File "/content/PAIMCS_model/paimcs/orthogonal.py", line 44, in call
    projection = tf.tensordot(x, self.W, axes=1) + self.b
                 ~~~~~~~~~~~~~~~~~~~~~~~~~~~~~~~~^~~~~~~~
tensorflow.python.framework.errors_impl.InvalidArgumentError: Exception encountered when calling OrthogonalRandomFeaturesTF.call().

[1m{{function_node __wrapped__AddV2_device_/job:localhost/replica:0/task:0/device:CPU:0}} Incompatible shapes: [4,8] vs. [16] [Op:AddV2] name: [0m

Arguments received by OrthogonalRandomFeaturesTF.call():
  â€¢ x=tf.Tensor(shape=(4, 8), dtype=float16)
  â€¢ training=False

======================================================================
ERROR: test_weight_and_bias_shapes (test_orthogonal.TestOrthogonalRandomFeaturesTF.test_weight_and_bias_shapes)
----------------------------------------------------------------------
Traceback (most recent call last):
  File "/content/PAIMCS_model/test_paimcs/test_orthogonal.py", line 28, in test_weight_and_bias_shapes
    _ = self.layer(self.input_tensor, training=False)
        ^^^^^^^^^^^^^^^^^^^^^^^^^^^^^^^^^^^^^^^^^^^^^
  File "/usr/local/lib/python3.11/dist-packages/keras/src/utils/traceback_utils.py", line 122, in error_handler
    raise e.with_traceback(filtered_tb) from None
  File "/content/PAIMCS_model/paimcs/orthogonal.py", line 44, in call
    projection = tf.tensordot(x, self.W, axes=1) + self.b
                 ~~~~~~~~~~~~~~~~~~~~~~~~~~~~~~~~^~~~~~~~
tensorflow.python.framework.errors_impl.InvalidArgumentError: Exception encountered when calling OrthogonalRandomFeaturesTF.call().

[1m{{function_node __wrapped__AddV2_device_/job:localhost/replica:0/task:0/device:CPU:0}} Incompatible shapes: [4,8] vs. [16] [Op:AddV2] name: [0m

Arguments received by OrthogonalRandomFeaturesTF.call():
  â€¢ x=tf.Tensor(shape=(4, 8), dtype=float16)
  â€¢ training=False

======================================================================
ERROR: test_forward_pass_time (test_performance.TestPerformance.test_forward_pass_time)
----------------------------------------------------------------------
Traceback (most recent call last):
  File "/content/PAIMCS_model/test_paimcs/test_performance.py", line 45, in test_forward_pass_time
    _ = self.model(self.token_seq, training=False)
        ^^^^^^^^^^^^^^^^^^^^^^^^^^^^^^^^^^^^^^^^^^
  File "/usr/local/lib/python3.11/dist-packages/keras/src/utils/traceback_utils.py", line 122, in error_handler
    raise e.with_traceback(filtered_tb) from None
  File "/content/PAIMCS_model/paimcs/lm.py", line 48, in call
    x = block(x, training=training)
        ^^^^^^^^^^^^^^^^^^^^^^^^^^^
  File "/content/PAIMCS_model/paimcs/performer.py", line 28, in call
    attn_out = self.attn(x, training=training)
               ^^^^^^^^^^^^^^^^^^^^^^^^^^^^^^^
  File "/content/PAIMCS_model/paimcs/attention.py", line 63, in call
    k_prime = self.favor_proj(k) # (batch, num_heads, seq_len, num_random_features)
              ^^^^^^^^^^^^^^^^^^
  File "/content/PAIMCS_model/paimcs/favor.py", line 35, in call
    x_proj = tensordot(x, self.W, axes=1) + self.bias
             ^^^^^^^^^^^^^^^^^^^^^^^^^^^^
tensorflow.python.framework.errors_impl.InvalidArgumentError: Exception encountered when calling FAVORProjection.call().

[1m{{function_node __wrapped__MatMul_device_/job:localhost/replica:0/task:0/device:CPU:0}} Matrix size-incompatible: In[0]: [320,8], In[1]: [4,8] [Op:MatMul] name: [0m

Arguments received by FAVORProjection.call():
  â€¢ x=tf.Tensor(shape=(4, 4, 20, 8), dtype=float16)

======================================================================
ERROR: test_dropout_variability (test_performer.TestKernelLMBlock.test_dropout_variability)
----------------------------------------------------------------------
Traceback (most recent call last):
  File "/content/PAIMCS_model/test_paimcs/test_performer.py", line 63, in test_dropout_variability
    output_train1 = block_dropout(self.input_tensor, training=True)
                    ^^^^^^^^^^^^^^^^^^^^^^^^^^^^^^^^^^^^^^^^^^^^^^^
  File "/usr/local/lib/python3.11/dist-packages/keras/src/utils/traceback_utils.py", line 122, in error_handler
    raise e.with_traceback(filtered_tb) from None
  File "/content/PAIMCS_model/paimcs/performer.py", line 28, in call
    attn_out = self.attn(x, training=training)
               ^^^^^^^^^^^^^^^^^^^^^^^^^^^^^^^
  File "/content/PAIMCS_model/paimcs/attention.py", line 63, in call
    k_prime = self.favor_proj(k) # (batch, num_heads, seq_len, num_random_features)
              ^^^^^^^^^^^^^^^^^^
  File "/content/PAIMCS_model/paimcs/favor.py", line 35, in call
    x_proj = tensordot(x, self.W, axes=1) + self.bias
             ^^^^^^^^^^^^^^^^^^^^^^^^^^^^
tensorflow.python.framework.errors_impl.InvalidArgumentError: Exception encountered when calling FAVORProjection.call().

[1m{{function_node __wrapped__MatMul_device_/job:localhost/replica:0/task:0/device:CPU:0}} Matrix size-incompatible: In[0]: [80,8], In[1]: [4,8] [Op:MatMul] name: [0m

Arguments received by FAVORProjection.call():
  â€¢ x=tf.Tensor(shape=(2, 4, 10, 8), dtype=float16)

======================================================================
ERROR: test_inference_determinism (test_performer.TestKernelLMBlock.test_inference_determinism)
----------------------------------------------------------------------
Traceback (most recent call last):
  File "/content/PAIMCS_model/test_paimcs/test_performer.py", line 46, in test_inference_determinism
    output1 = self.block(self.input_tensor, training=False)
              ^^^^^^^^^^^^^^^^^^^^^^^^^^^^^^^^^^^^^^^^^^^^^
  File "/usr/local/lib/python3.11/dist-packages/keras/src/utils/traceback_utils.py", line 122, in error_handler
    raise e.with_traceback(filtered_tb) from None
  File "/content/PAIMCS_model/paimcs/performer.py", line 28, in call
    attn_out = self.attn(x, training=training)
               ^^^^^^^^^^^^^^^^^^^^^^^^^^^^^^^
  File "/content/PAIMCS_model/paimcs/attention.py", line 63, in call
    k_prime = self.favor_proj(k) # (batch, num_heads, seq_len, num_random_features)
              ^^^^^^^^^^^^^^^^^^
  File "/content/PAIMCS_model/paimcs/favor.py", line 35, in call
    x_proj = tensordot(x, self.W, axes=1) + self.bias
             ^^^^^^^^^^^^^^^^^^^^^^^^^^^^
tensorflow.python.framework.errors_impl.InvalidArgumentError: Exception encountered when calling FAVORProjection.call().

[1m{{function_node __wrapped__MatMul_device_/job:localhost/replica:0/task:0/device:CPU:0}} Matrix size-incompatible: In[0]: [80,8], In[1]: [4,8] [Op:MatMul] name: [0m

Arguments received by FAVORProjection.call():
  â€¢ x=tf.Tensor(shape=(2, 4, 10, 8), dtype=float16)

======================================================================
ERROR: test_output_shape (test_performer.TestKernelLMBlock.test_output_shape)
----------------------------------------------------------------------
Traceback (most recent call last):
  File "/content/PAIMCS_model/test_paimcs/test_performer.py", line 41, in test_output_shape
    output = self.block(self.input_tensor, training=False)
             ^^^^^^^^^^^^^^^^^^^^^^^^^^^^^^^^^^^^^^^^^^^^^
  File "/usr/local/lib/python3.11/dist-packages/keras/src/utils/traceback_utils.py", line 122, in error_handler
    raise e.with_traceback(filtered_tb) from None
  File "/content/PAIMCS_model/paimcs/performer.py", line 28, in call
    attn_out = self.attn(x, training=training)
               ^^^^^^^^^^^^^^^^^^^^^^^^^^^^^^^
  File "/content/PAIMCS_model/paimcs/attention.py", line 63, in call
    k_prime = self.favor_proj(k) # (batch, num_heads, seq_len, num_random_features)
              ^^^^^^^^^^^^^^^^^^
  File "/content/PAIMCS_model/paimcs/favor.py", line 35, in call
    x_proj = tensordot(x, self.W, axes=1) + self.bias
             ^^^^^^^^^^^^^^^^^^^^^^^^^^^^
tensorflow.python.framework.errors_impl.InvalidArgumentError: Exception encountered when calling FAVORProjection.call().

[1m{{function_node __wrapped__MatMul_device_/job:localhost/replica:0/task:0/device:CPU:0}} Matrix size-incompatible: In[0]: [80,8], In[1]: [4,8] [Op:MatMul] name: [0m

Arguments received by FAVORProjection.call():
  â€¢ x=tf.Tensor(shape=(2, 4, 10, 8), dtype=float16)

======================================================================
ERROR: test_reproducible_output (test_reproducibility.TestReproducibility.test_reproducible_output)
----------------------------------------------------------------------
Traceback (most recent call last):
  File "/content/PAIMCS_model/test_paimcs/test_reproducibility.py", line 42, in test_reproducible_output
    output1 = model1(token_seq1, training=False)
              ^^^^^^^^^^^^^^^^^^^^^^^^^^^^^^^^^^
  File "/usr/local/lib/python3.11/dist-packages/keras/src/utils/traceback_utils.py", line 122, in error_handler
    raise e.with_traceback(filtered_tb) from None
  File "/content/PAIMCS_model/paimcs/lm.py", line 48, in call
    x = block(x, training=training)
        ^^^^^^^^^^^^^^^^^^^^^^^^^^^
  File "/content/PAIMCS_model/paimcs/performer.py", line 28, in call
    attn_out = self.attn(x, training=training)
               ^^^^^^^^^^^^^^^^^^^^^^^^^^^^^^^
  File "/content/PAIMCS_model/paimcs/attention.py", line 63, in call
    k_prime = self.favor_proj(k) # (batch, num_heads, seq_len, num_random_features)
              ^^^^^^^^^^^^^^^^^^
  File "/content/PAIMCS_model/paimcs/favor.py", line 35, in call
    x_proj = tensordot(x, self.W, axes=1) + self.bias
             ^^^^^^^^^^^^^^^^^^^^^^^^^^^^
tensorflow.python.framework.errors_impl.InvalidArgumentError: Exception encountered when calling FAVORProjection.call().

[1m{{function_node __wrapped__MatMul_device_/job:localhost/replica:0/task:0/device:CPU:0}} Matrix size-incompatible: In[0]: [160,8], In[1]: [4,8] [Op:MatMul] name: [0m

Arguments received by FAVORProjection.call():
  â€¢ x=tf.Tensor(shape=(2, 4, 20, 8), dtype=float16)

----------------------------------------------------------------------
Ran 46 tests in 15.367s

FAILED (errors=21)
