2025-05-08 16:22:40.453403: E external/local_xla/xla/stream_executor/cuda/cuda_fft.cc:477] Unable to register cuFFT factory: Attempting to register factory for plugin cuFFT when one has already been registered
WARNING: All log messages before absl::InitializeLog() is called are written to STDERR
E0000 00:00:1746721360.651017      88 cuda_dnn.cc:8310] Unable to register cuDNN factory: Attempting to register factory for plugin cuDNN when one has already been registered
E0000 00:00:1746721360.708696      88 cuda_blas.cc:1418] Unable to register cuBLAS factory: Attempting to register factory for plugin cuBLAS when one has already been registered
I0000 00:00:1746721373.104108      88 gpu_device.cc:2022] Created device /job:localhost/replica:0/task:0/device:GPU:0 with 15513 MB memory:  -> device: 0, name: Tesla P100-PCIE-16GB, pci bus id: 0000:00:04.0, compute capability: 6.0
Found 31 text files for training.
Epoch 1/4
WARNING: All log messages before absl::InitializeLog() is called are written to STDERR
I0000 00:00:1746722278.489444     111 service.cc:148] XLA service 0x78f6e00031d0 initialized for platform CUDA (this does not guarantee that XLA will be used). Devices:
I0000 00:00:1746722278.490678     111 service.cc:156]   StreamExecutor device (0): Tesla P100-PCIE-16GB, Compute Capability 6.0
Traceback (most recent call last):
  File "/kaggle/working/PAIMCS_model/train/train.py", line 104, in <module>
    model.fit(train_ds, validation_data=val_ds, epochs=4, steps_per_epoch=5310, validation_steps=201, callbacks=callbacks)
  File "/usr/local/lib/python3.11/dist-packages/keras/src/utils/traceback_utils.py", line 122, in error_handler
    raise e.with_traceback(filtered_tb) from None
  File "/usr/local/lib/python3.11/dist-packages/tensorflow/python/eager/execute.py", line 53, in quick_execute
    tensors = pywrap_tfe.TFE_Py_Execute(ctx._handle, device_name, op_name,
  ^^^^^^^^^^^^^^^^^^^^^^^^^^^^^^^^^^^^^^^^^^^^^^^^^^^^^^^^^^^^^^^^^^^^^^^^
tensorflow.python.framework.errors_impl.InvalidArgumentError: Graph execution error:

Detected at node functional_27_1/Add defined at (most recent call last):
<stack traces unavailable>
Incompatible shapes: [128,114,243] vs. [1032,243]
	 [[{{node functional_27_1/Add}}]]
	tf2xla conversion failed while converting __inference_one_step_on_data_276450[]. Run with TF_DUMP_GRAPH_PREFIX=/path/to/dump/dir and --vmodule=xla_compiler=2 to obtain a dump of the compiled functions.
	 [[StatefulPartitionedCall]] [Op:__inference_one_step_on_iterator_278909]
